[2024-11-17T16:44:19.548+0000] {local_task_job_runner.py:123} INFO - ::group::Pre task execution logs
[2024-11-17T16:44:19.558+0000] {taskinstance.py:2613} INFO - Dependencies all met for dep_context=non-requeueable deps ti=<TaskInstance: dbt_local_dag.dbt_run manual__2024-11-17T16:39:09.381848+00:00 [queued]>
[2024-11-17T16:44:19.565+0000] {taskinstance.py:2613} INFO - Dependencies all met for dep_context=requeueable deps ti=<TaskInstance: dbt_local_dag.dbt_run manual__2024-11-17T16:39:09.381848+00:00 [queued]>
[2024-11-17T16:44:19.566+0000] {taskinstance.py:2866} INFO - Starting attempt 2 of 2
[2024-11-17T16:44:19.595+0000] {taskinstance.py:2889} INFO - Executing <Task(BashOperator): dbt_run> on 2024-11-17 16:39:09.381848+00:00
[2024-11-17T16:44:19.600+0000] {standard_task_runner.py:72} INFO - Started process 124 to run task
[2024-11-17T16:44:19.603+0000] {standard_task_runner.py:104} INFO - Running: ['airflow', 'tasks', 'run', 'dbt_local_dag', 'dbt_run', 'manual__2024-11-17T16:39:09.381848+00:00', '--job-id', '30', '--raw', '--subdir', 'DAGS_FOLDER/main.py', '--cfg-path', '/tmp/tmpqj4aekqk']
[2024-11-17T16:44:19.604+0000] {standard_task_runner.py:105} INFO - Job 30: Subtask dbt_run
[2024-11-17T16:44:19.648+0000] {task_command.py:467} INFO - Running <TaskInstance: dbt_local_dag.dbt_run manual__2024-11-17T16:39:09.381848+00:00 [running]> on host 08c8566fb4d1
[2024-11-17T16:44:19.714+0000] {taskinstance.py:3132} INFO - Exporting env vars: AIRFLOW_CTX_DAG_OWNER='airflow' AIRFLOW_CTX_DAG_ID='dbt_local_dag' AIRFLOW_CTX_TASK_ID='dbt_run' AIRFLOW_CTX_EXECUTION_DATE='2024-11-17T16:39:09.381848+00:00' AIRFLOW_CTX_TRY_NUMBER='2' AIRFLOW_CTX_DAG_RUN_ID='manual__2024-11-17T16:39:09.381848+00:00'
[2024-11-17T16:44:19.715+0000] {taskinstance.py:731} INFO - ::endgroup::
[2024-11-17T16:44:19.730+0000] {subprocess.py:78} INFO - Tmp dir root location: /tmp
[2024-11-17T16:44:19.731+0000] {subprocess.py:88} INFO - Running command: ['/usr/bin/bash', '-c', 'cd /opt/airflow/dbt_project && dbt run']
[2024-11-17T16:44:19.739+0000] {subprocess.py:99} INFO - Output:
[2024-11-17T16:44:21.323+0000] {subprocess.py:106} INFO - Usage: dbt run [OPTIONS]
[2024-11-17T16:44:21.323+0000] {subprocess.py:106} INFO - Try 'dbt run -h' for help.
[2024-11-17T16:44:21.323+0000] {subprocess.py:106} INFO - 
[2024-11-17T16:44:21.324+0000] {subprocess.py:106} INFO - Error: Invalid value for '--profiles-dir': Path '/root/.dbt' does not exist.
[2024-11-17T16:44:21.596+0000] {subprocess.py:110} INFO - Command exited with return code 2
[2024-11-17T16:44:21.603+0000] {taskinstance.py:3311} ERROR - Task failed with exception
Traceback (most recent call last):
  File "/home/airflow/.local/lib/python3.12/site-packages/airflow/models/taskinstance.py", line 767, in _execute_task
    result = _execute_callable(context=context, **execute_callable_kwargs)
             ^^^^^^^^^^^^^^^^^^^^^^^^^^^^^^^^^^^^^^^^^^^^^^^^^^^^^^^^^^^^^
  File "/home/airflow/.local/lib/python3.12/site-packages/airflow/models/taskinstance.py", line 733, in _execute_callable
    return ExecutionCallableRunner(
           ^^^^^^^^^^^^^^^^^^^^^^^^
  File "/home/airflow/.local/lib/python3.12/site-packages/airflow/utils/operator_helpers.py", line 252, in run
    return self.func(*args, **kwargs)
           ^^^^^^^^^^^^^^^^^^^^^^^^^^
  File "/home/airflow/.local/lib/python3.12/site-packages/airflow/models/baseoperator.py", line 417, in wrapper
    return func(self, *args, **kwargs)
           ^^^^^^^^^^^^^^^^^^^^^^^^^^^
  File "/home/airflow/.local/lib/python3.12/site-packages/airflow/operators/bash.py", line 276, in execute
    raise AirflowException(
airflow.exceptions.AirflowException: Bash command failed. The command returned a non-zero exit code 2.
[2024-11-17T16:44:21.606+0000] {taskinstance.py:1225} INFO - Marking task as FAILED. dag_id=dbt_local_dag, task_id=dbt_run, run_id=manual__2024-11-17T16:39:09.381848+00:00, execution_date=20241117T163909, start_date=20241117T164419, end_date=20241117T164421
[2024-11-17T16:44:21.635+0000] {taskinstance.py:340} INFO - ::group::Post task execution logs
[2024-11-17T16:44:21.635+0000] {standard_task_runner.py:124} ERROR - Failed to execute job 30 for task dbt_run (Bash command failed. The command returned a non-zero exit code 2.; 124)
Traceback (most recent call last):
  File "/home/airflow/.local/lib/python3.12/site-packages/airflow/task/task_runner/standard_task_runner.py", line 117, in _start_by_fork
    ret = args.func(args, dag=self.dag)
          ^^^^^^^^^^^^^^^^^^^^^^^^^^^^^
  File "/home/airflow/.local/lib/python3.12/site-packages/airflow/cli/cli_config.py", line 49, in command
    return func(*args, **kwargs)
           ^^^^^^^^^^^^^^^^^^^^^
  File "/home/airflow/.local/lib/python3.12/site-packages/airflow/utils/cli.py", line 116, in wrapper
    return f(*args, **kwargs)
           ^^^^^^^^^^^^^^^^^^
  File "/home/airflow/.local/lib/python3.12/site-packages/airflow/cli/commands/task_command.py", line 483, in task_run
    task_return_code = _run_task_by_selected_method(args, _dag, ti)
                       ^^^^^^^^^^^^^^^^^^^^^^^^^^^^^^^^^^^^^^^^^^^^
  File "/home/airflow/.local/lib/python3.12/site-packages/airflow/cli/commands/task_command.py", line 256, in _run_task_by_selected_method
    return _run_raw_task(args, ti)
           ^^^^^^^^^^^^^^^^^^^^^^^
  File "/home/airflow/.local/lib/python3.12/site-packages/airflow/cli/commands/task_command.py", line 341, in _run_raw_task
    return ti._run_raw_task(
           ^^^^^^^^^^^^^^^^^
  File "/home/airflow/.local/lib/python3.12/site-packages/airflow/utils/session.py", line 97, in wrapper
    return func(*args, session=session, **kwargs)
           ^^^^^^^^^^^^^^^^^^^^^^^^^^^^^^^^^^^^^^
  File "/home/airflow/.local/lib/python3.12/site-packages/airflow/models/taskinstance.py", line 3005, in _run_raw_task
    return _run_raw_task(
           ^^^^^^^^^^^^^^
  File "/home/airflow/.local/lib/python3.12/site-packages/airflow/models/taskinstance.py", line 273, in _run_raw_task
    TaskInstance._execute_task_with_callbacks(
  File "/home/airflow/.local/lib/python3.12/site-packages/airflow/models/taskinstance.py", line 3159, in _execute_task_with_callbacks
    result = self._execute_task(context, task_orig)
             ^^^^^^^^^^^^^^^^^^^^^^^^^^^^^^^^^^^^^^
  File "/home/airflow/.local/lib/python3.12/site-packages/airflow/models/taskinstance.py", line 3183, in _execute_task
    return _execute_task(self, context, task_orig)
           ^^^^^^^^^^^^^^^^^^^^^^^^^^^^^^^^^^^^^^^
  File "/home/airflow/.local/lib/python3.12/site-packages/airflow/models/taskinstance.py", line 767, in _execute_task
    result = _execute_callable(context=context, **execute_callable_kwargs)
             ^^^^^^^^^^^^^^^^^^^^^^^^^^^^^^^^^^^^^^^^^^^^^^^^^^^^^^^^^^^^^
  File "/home/airflow/.local/lib/python3.12/site-packages/airflow/models/taskinstance.py", line 733, in _execute_callable
    return ExecutionCallableRunner(
           ^^^^^^^^^^^^^^^^^^^^^^^^
  File "/home/airflow/.local/lib/python3.12/site-packages/airflow/utils/operator_helpers.py", line 252, in run
    return self.func(*args, **kwargs)
           ^^^^^^^^^^^^^^^^^^^^^^^^^^
  File "/home/airflow/.local/lib/python3.12/site-packages/airflow/models/baseoperator.py", line 417, in wrapper
    return func(self, *args, **kwargs)
           ^^^^^^^^^^^^^^^^^^^^^^^^^^^
  File "/home/airflow/.local/lib/python3.12/site-packages/airflow/operators/bash.py", line 276, in execute
    raise AirflowException(
airflow.exceptions.AirflowException: Bash command failed. The command returned a non-zero exit code 2.
[2024-11-17T16:44:21.661+0000] {local_task_job_runner.py:266} INFO - Task exited with return code 1
[2024-11-17T16:44:21.677+0000] {taskinstance.py:3895} INFO - 0 downstream tasks scheduled from follow-on schedule check
[2024-11-17T16:44:21.694+0000] {local_task_job_runner.py:245} INFO - ::endgroup::
