[2024-11-17T16:42:33.706+0000] {local_task_job_runner.py:123} INFO - ::group::Pre task execution logs
[2024-11-17T16:42:33.714+0000] {taskinstance.py:2613} INFO - Dependencies all met for dep_context=non-requeueable deps ti=<TaskInstance: dbt_local_dag.dbt_run manual__2024-11-17T16:37:20.170608+00:00 [queued]>
[2024-11-17T16:42:33.718+0000] {taskinstance.py:2613} INFO - Dependencies all met for dep_context=requeueable deps ti=<TaskInstance: dbt_local_dag.dbt_run manual__2024-11-17T16:37:20.170608+00:00 [queued]>
[2024-11-17T16:42:33.719+0000] {taskinstance.py:2866} INFO - Starting attempt 2 of 2
[2024-11-17T16:42:33.747+0000] {taskinstance.py:2889} INFO - Executing <Task(BashOperator): dbt_run> on 2024-11-17 16:37:20.170608+00:00
[2024-11-17T16:42:33.752+0000] {standard_task_runner.py:72} INFO - Started process 108 to run task
[2024-11-17T16:42:33.756+0000] {standard_task_runner.py:104} INFO - Running: ['airflow', 'tasks', 'run', 'dbt_local_dag', 'dbt_run', 'manual__2024-11-17T16:37:20.170608+00:00', '--job-id', '29', '--raw', '--subdir', 'DAGS_FOLDER/main.py', '--cfg-path', '/tmp/tmpz2fifzw4']
[2024-11-17T16:42:33.757+0000] {standard_task_runner.py:105} INFO - Job 29: Subtask dbt_run
[2024-11-17T16:42:33.801+0000] {task_command.py:467} INFO - Running <TaskInstance: dbt_local_dag.dbt_run manual__2024-11-17T16:37:20.170608+00:00 [running]> on host 08c8566fb4d1
[2024-11-17T16:42:33.856+0000] {taskinstance.py:3132} INFO - Exporting env vars: AIRFLOW_CTX_DAG_OWNER='airflow' AIRFLOW_CTX_DAG_ID='dbt_local_dag' AIRFLOW_CTX_TASK_ID='dbt_run' AIRFLOW_CTX_EXECUTION_DATE='2024-11-17T16:37:20.170608+00:00' AIRFLOW_CTX_TRY_NUMBER='2' AIRFLOW_CTX_DAG_RUN_ID='manual__2024-11-17T16:37:20.170608+00:00'
[2024-11-17T16:42:33.856+0000] {taskinstance.py:731} INFO - ::endgroup::
[2024-11-17T16:42:33.869+0000] {subprocess.py:78} INFO - Tmp dir root location: /tmp
[2024-11-17T16:42:33.869+0000] {subprocess.py:88} INFO - Running command: ['/usr/bin/bash', '-c', 'cd /opt/airflow/dbt_project && dbt run']
[2024-11-17T16:42:33.879+0000] {subprocess.py:99} INFO - Output:
[2024-11-17T16:42:35.128+0000] {subprocess.py:106} INFO - Usage: dbt run [OPTIONS]
[2024-11-17T16:42:35.129+0000] {subprocess.py:106} INFO - Try 'dbt run -h' for help.
[2024-11-17T16:42:35.129+0000] {subprocess.py:106} INFO - 
[2024-11-17T16:42:35.129+0000] {subprocess.py:106} INFO - Error: Invalid value for '--profiles-dir': Path '/root/.dbt' does not exist.
[2024-11-17T16:42:35.289+0000] {subprocess.py:110} INFO - Command exited with return code 2
[2024-11-17T16:42:35.293+0000] {taskinstance.py:3311} ERROR - Task failed with exception
Traceback (most recent call last):
  File "/home/airflow/.local/lib/python3.12/site-packages/airflow/models/taskinstance.py", line 767, in _execute_task
    result = _execute_callable(context=context, **execute_callable_kwargs)
             ^^^^^^^^^^^^^^^^^^^^^^^^^^^^^^^^^^^^^^^^^^^^^^^^^^^^^^^^^^^^^
  File "/home/airflow/.local/lib/python3.12/site-packages/airflow/models/taskinstance.py", line 733, in _execute_callable
    return ExecutionCallableRunner(
           ^^^^^^^^^^^^^^^^^^^^^^^^
  File "/home/airflow/.local/lib/python3.12/site-packages/airflow/utils/operator_helpers.py", line 252, in run
    return self.func(*args, **kwargs)
           ^^^^^^^^^^^^^^^^^^^^^^^^^^
  File "/home/airflow/.local/lib/python3.12/site-packages/airflow/models/baseoperator.py", line 417, in wrapper
    return func(self, *args, **kwargs)
           ^^^^^^^^^^^^^^^^^^^^^^^^^^^
  File "/home/airflow/.local/lib/python3.12/site-packages/airflow/operators/bash.py", line 276, in execute
    raise AirflowException(
airflow.exceptions.AirflowException: Bash command failed. The command returned a non-zero exit code 2.
[2024-11-17T16:42:35.296+0000] {taskinstance.py:1225} INFO - Marking task as FAILED. dag_id=dbt_local_dag, task_id=dbt_run, run_id=manual__2024-11-17T16:37:20.170608+00:00, execution_date=20241117T163720, start_date=20241117T164233, end_date=20241117T164235
[2024-11-17T16:42:35.792+0000] {taskinstance.py:340} INFO - ::group::Post task execution logs
[2024-11-17T16:42:35.792+0000] {standard_task_runner.py:124} ERROR - Failed to execute job 29 for task dbt_run (Bash command failed. The command returned a non-zero exit code 2.; 108)
Traceback (most recent call last):
  File "/home/airflow/.local/lib/python3.12/site-packages/airflow/task/task_runner/standard_task_runner.py", line 117, in _start_by_fork
    ret = args.func(args, dag=self.dag)
          ^^^^^^^^^^^^^^^^^^^^^^^^^^^^^
  File "/home/airflow/.local/lib/python3.12/site-packages/airflow/cli/cli_config.py", line 49, in command
    return func(*args, **kwargs)
           ^^^^^^^^^^^^^^^^^^^^^
  File "/home/airflow/.local/lib/python3.12/site-packages/airflow/utils/cli.py", line 116, in wrapper
    return f(*args, **kwargs)
           ^^^^^^^^^^^^^^^^^^
  File "/home/airflow/.local/lib/python3.12/site-packages/airflow/cli/commands/task_command.py", line 483, in task_run
    task_return_code = _run_task_by_selected_method(args, _dag, ti)
                       ^^^^^^^^^^^^^^^^^^^^^^^^^^^^^^^^^^^^^^^^^^^^
  File "/home/airflow/.local/lib/python3.12/site-packages/airflow/cli/commands/task_command.py", line 256, in _run_task_by_selected_method
    return _run_raw_task(args, ti)
           ^^^^^^^^^^^^^^^^^^^^^^^
  File "/home/airflow/.local/lib/python3.12/site-packages/airflow/cli/commands/task_command.py", line 341, in _run_raw_task
    return ti._run_raw_task(
           ^^^^^^^^^^^^^^^^^
  File "/home/airflow/.local/lib/python3.12/site-packages/airflow/utils/session.py", line 97, in wrapper
    return func(*args, session=session, **kwargs)
           ^^^^^^^^^^^^^^^^^^^^^^^^^^^^^^^^^^^^^^
  File "/home/airflow/.local/lib/python3.12/site-packages/airflow/models/taskinstance.py", line 3005, in _run_raw_task
    return _run_raw_task(
           ^^^^^^^^^^^^^^
  File "/home/airflow/.local/lib/python3.12/site-packages/airflow/models/taskinstance.py", line 273, in _run_raw_task
    TaskInstance._execute_task_with_callbacks(
  File "/home/airflow/.local/lib/python3.12/site-packages/airflow/models/taskinstance.py", line 3159, in _execute_task_with_callbacks
    result = self._execute_task(context, task_orig)
             ^^^^^^^^^^^^^^^^^^^^^^^^^^^^^^^^^^^^^^
  File "/home/airflow/.local/lib/python3.12/site-packages/airflow/models/taskinstance.py", line 3183, in _execute_task
    return _execute_task(self, context, task_orig)
           ^^^^^^^^^^^^^^^^^^^^^^^^^^^^^^^^^^^^^^^
  File "/home/airflow/.local/lib/python3.12/site-packages/airflow/models/taskinstance.py", line 767, in _execute_task
    result = _execute_callable(context=context, **execute_callable_kwargs)
             ^^^^^^^^^^^^^^^^^^^^^^^^^^^^^^^^^^^^^^^^^^^^^^^^^^^^^^^^^^^^^
  File "/home/airflow/.local/lib/python3.12/site-packages/airflow/models/taskinstance.py", line 733, in _execute_callable
    return ExecutionCallableRunner(
           ^^^^^^^^^^^^^^^^^^^^^^^^
  File "/home/airflow/.local/lib/python3.12/site-packages/airflow/utils/operator_helpers.py", line 252, in run
    return self.func(*args, **kwargs)
           ^^^^^^^^^^^^^^^^^^^^^^^^^^
  File "/home/airflow/.local/lib/python3.12/site-packages/airflow/models/baseoperator.py", line 417, in wrapper
    return func(self, *args, **kwargs)
           ^^^^^^^^^^^^^^^^^^^^^^^^^^^
  File "/home/airflow/.local/lib/python3.12/site-packages/airflow/operators/bash.py", line 276, in execute
    raise AirflowException(
airflow.exceptions.AirflowException: Bash command failed. The command returned a non-zero exit code 2.
[2024-11-17T16:42:35.813+0000] {local_task_job_runner.py:266} INFO - Task exited with return code 1
[2024-11-17T16:42:35.824+0000] {taskinstance.py:3895} INFO - 0 downstream tasks scheduled from follow-on schedule check
[2024-11-17T16:42:35.835+0000] {local_task_job_runner.py:245} INFO - ::endgroup::
