[2024-11-17T17:30:10.465+0000] {local_task_job_runner.py:123} INFO - ::group::Pre task execution logs
[2024-11-17T17:30:10.476+0000] {taskinstance.py:2613} INFO - Dependencies all met for dep_context=non-requeueable deps ti=<TaskInstance: etl_pipeline_dag.dbt_test manual__2024-11-17T17:30:02.011089+00:00 [queued]>
[2024-11-17T17:30:10.482+0000] {taskinstance.py:2613} INFO - Dependencies all met for dep_context=requeueable deps ti=<TaskInstance: etl_pipeline_dag.dbt_test manual__2024-11-17T17:30:02.011089+00:00 [queued]>
[2024-11-17T17:30:10.482+0000] {taskinstance.py:2866} INFO - Starting attempt 1 of 2
[2024-11-17T17:30:10.513+0000] {taskinstance.py:2889} INFO - Executing <Task(BashOperator): dbt_test> on 2024-11-17 17:30:02.011089+00:00
[2024-11-17T17:30:10.517+0000] {standard_task_runner.py:72} INFO - Started process 204 to run task
[2024-11-17T17:30:10.519+0000] {standard_task_runner.py:104} INFO - Running: ['airflow', 'tasks', 'run', 'etl_pipeline_dag', 'dbt_test', 'manual__2024-11-17T17:30:02.011089+00:00', '--job-id', '40', '--raw', '--subdir', 'DAGS_FOLDER/main.py', '--cfg-path', '/tmp/tmp_hj32bnx']
[2024-11-17T17:30:10.520+0000] {standard_task_runner.py:105} INFO - Job 40: Subtask dbt_test
[2024-11-17T17:30:10.565+0000] {task_command.py:467} INFO - Running <TaskInstance: etl_pipeline_dag.dbt_test manual__2024-11-17T17:30:02.011089+00:00 [running]> on host 0441811e6393
[2024-11-17T17:30:10.664+0000] {taskinstance.py:3132} INFO - Exporting env vars: AIRFLOW_CTX_DAG_OWNER='airflow' AIRFLOW_CTX_DAG_ID='etl_pipeline_dag' AIRFLOW_CTX_TASK_ID='dbt_test' AIRFLOW_CTX_EXECUTION_DATE='2024-11-17T17:30:02.011089+00:00' AIRFLOW_CTX_TRY_NUMBER='1' AIRFLOW_CTX_DAG_RUN_ID='manual__2024-11-17T17:30:02.011089+00:00'
[2024-11-17T17:30:10.664+0000] {taskinstance.py:731} INFO - ::endgroup::
[2024-11-17T17:30:10.682+0000] {subprocess.py:78} INFO - Tmp dir root location: /tmp
[2024-11-17T17:30:10.683+0000] {subprocess.py:88} INFO - Running command: ['/usr/bin/bash', '-c', 'cd /opt/airflow/dbt_project && dbt test']
[2024-11-17T17:30:10.691+0000] {subprocess.py:99} INFO - Output:
[2024-11-17T17:30:12.572+0000] {subprocess.py:106} INFO - Usage: dbt test [OPTIONS]
[2024-11-17T17:30:12.573+0000] {subprocess.py:106} INFO - Try 'dbt test -h' for help.
[2024-11-17T17:30:12.574+0000] {subprocess.py:106} INFO - 
[2024-11-17T17:30:12.575+0000] {subprocess.py:106} INFO - Error: Invalid value for '--profiles-dir': Path '/root/.dbt' does not exist.
[2024-11-17T17:30:13.154+0000] {subprocess.py:110} INFO - Command exited with return code 2
[2024-11-17T17:30:13.167+0000] {taskinstance.py:3311} ERROR - Task failed with exception
Traceback (most recent call last):
  File "/home/airflow/.local/lib/python3.12/site-packages/airflow/models/taskinstance.py", line 767, in _execute_task
    result = _execute_callable(context=context, **execute_callable_kwargs)
             ^^^^^^^^^^^^^^^^^^^^^^^^^^^^^^^^^^^^^^^^^^^^^^^^^^^^^^^^^^^^^
  File "/home/airflow/.local/lib/python3.12/site-packages/airflow/models/taskinstance.py", line 733, in _execute_callable
    return ExecutionCallableRunner(
           ^^^^^^^^^^^^^^^^^^^^^^^^
  File "/home/airflow/.local/lib/python3.12/site-packages/airflow/utils/operator_helpers.py", line 252, in run
    return self.func(*args, **kwargs)
           ^^^^^^^^^^^^^^^^^^^^^^^^^^
  File "/home/airflow/.local/lib/python3.12/site-packages/airflow/models/baseoperator.py", line 417, in wrapper
    return func(self, *args, **kwargs)
           ^^^^^^^^^^^^^^^^^^^^^^^^^^^
  File "/home/airflow/.local/lib/python3.12/site-packages/airflow/operators/bash.py", line 276, in execute
    raise AirflowException(
airflow.exceptions.AirflowException: Bash command failed. The command returned a non-zero exit code 2.
[2024-11-17T17:30:13.181+0000] {taskinstance.py:1225} INFO - Marking task as UP_FOR_RETRY. dag_id=etl_pipeline_dag, task_id=dbt_test, run_id=manual__2024-11-17T17:30:02.011089+00:00, execution_date=20241117T173002, start_date=20241117T173010, end_date=20241117T173013
[2024-11-17T17:30:13.226+0000] {taskinstance.py:340} INFO - ::group::Post task execution logs
[2024-11-17T17:30:13.227+0000] {standard_task_runner.py:124} ERROR - Failed to execute job 40 for task dbt_test (Bash command failed. The command returned a non-zero exit code 2.; 204)
Traceback (most recent call last):
  File "/home/airflow/.local/lib/python3.12/site-packages/airflow/task/task_runner/standard_task_runner.py", line 117, in _start_by_fork
    ret = args.func(args, dag=self.dag)
          ^^^^^^^^^^^^^^^^^^^^^^^^^^^^^
  File "/home/airflow/.local/lib/python3.12/site-packages/airflow/cli/cli_config.py", line 49, in command
    return func(*args, **kwargs)
           ^^^^^^^^^^^^^^^^^^^^^
  File "/home/airflow/.local/lib/python3.12/site-packages/airflow/utils/cli.py", line 116, in wrapper
    return f(*args, **kwargs)
           ^^^^^^^^^^^^^^^^^^
  File "/home/airflow/.local/lib/python3.12/site-packages/airflow/cli/commands/task_command.py", line 483, in task_run
    task_return_code = _run_task_by_selected_method(args, _dag, ti)
                       ^^^^^^^^^^^^^^^^^^^^^^^^^^^^^^^^^^^^^^^^^^^^
  File "/home/airflow/.local/lib/python3.12/site-packages/airflow/cli/commands/task_command.py", line 256, in _run_task_by_selected_method
    return _run_raw_task(args, ti)
           ^^^^^^^^^^^^^^^^^^^^^^^
  File "/home/airflow/.local/lib/python3.12/site-packages/airflow/cli/commands/task_command.py", line 341, in _run_raw_task
    return ti._run_raw_task(
           ^^^^^^^^^^^^^^^^^
  File "/home/airflow/.local/lib/python3.12/site-packages/airflow/utils/session.py", line 97, in wrapper
    return func(*args, session=session, **kwargs)
           ^^^^^^^^^^^^^^^^^^^^^^^^^^^^^^^^^^^^^^
  File "/home/airflow/.local/lib/python3.12/site-packages/airflow/models/taskinstance.py", line 3005, in _run_raw_task
    return _run_raw_task(
           ^^^^^^^^^^^^^^
  File "/home/airflow/.local/lib/python3.12/site-packages/airflow/models/taskinstance.py", line 273, in _run_raw_task
    TaskInstance._execute_task_with_callbacks(
  File "/home/airflow/.local/lib/python3.12/site-packages/airflow/models/taskinstance.py", line 3159, in _execute_task_with_callbacks
    result = self._execute_task(context, task_orig)
             ^^^^^^^^^^^^^^^^^^^^^^^^^^^^^^^^^^^^^^
  File "/home/airflow/.local/lib/python3.12/site-packages/airflow/models/taskinstance.py", line 3183, in _execute_task
    return _execute_task(self, context, task_orig)
           ^^^^^^^^^^^^^^^^^^^^^^^^^^^^^^^^^^^^^^^
  File "/home/airflow/.local/lib/python3.12/site-packages/airflow/models/taskinstance.py", line 767, in _execute_task
    result = _execute_callable(context=context, **execute_callable_kwargs)
             ^^^^^^^^^^^^^^^^^^^^^^^^^^^^^^^^^^^^^^^^^^^^^^^^^^^^^^^^^^^^^
  File "/home/airflow/.local/lib/python3.12/site-packages/airflow/models/taskinstance.py", line 733, in _execute_callable
    return ExecutionCallableRunner(
           ^^^^^^^^^^^^^^^^^^^^^^^^
  File "/home/airflow/.local/lib/python3.12/site-packages/airflow/utils/operator_helpers.py", line 252, in run
    return self.func(*args, **kwargs)
           ^^^^^^^^^^^^^^^^^^^^^^^^^^
  File "/home/airflow/.local/lib/python3.12/site-packages/airflow/models/baseoperator.py", line 417, in wrapper
    return func(self, *args, **kwargs)
           ^^^^^^^^^^^^^^^^^^^^^^^^^^^
  File "/home/airflow/.local/lib/python3.12/site-packages/airflow/operators/bash.py", line 276, in execute
    raise AirflowException(
airflow.exceptions.AirflowException: Bash command failed. The command returned a non-zero exit code 2.
[2024-11-17T17:30:13.274+0000] {local_task_job_runner.py:266} INFO - Task exited with return code 1
[2024-11-17T17:30:13.291+0000] {taskinstance.py:3895} INFO - 0 downstream tasks scheduled from follow-on schedule check
[2024-11-17T17:30:13.293+0000] {local_task_job_runner.py:245} INFO - ::endgroup::
